2024-07-05 21:45:11,817 INFO    MainThread:43406 [wandb_setup.py:_flush():76] Current SDK version is 0.17.4
2024-07-05 21:45:11,818 INFO    MainThread:43406 [wandb_setup.py:_flush():76] Configure stats pid to 43406
2024-07-05 21:45:11,818 INFO    MainThread:43406 [wandb_setup.py:_flush():76] Loading settings from /home/gaston/.config/wandb/settings
2024-07-05 21:45:11,819 INFO    MainThread:43406 [wandb_setup.py:_flush():76] Loading settings from /media/gaston/gaston1/DEV/ACTIA/workstation/scripts/wandb/settings
2024-07-05 21:45:11,819 INFO    MainThread:43406 [wandb_setup.py:_flush():76] Loading settings from environment variables: {'api_key': '***REDACTED***', 'root_dir': '/media/gaston/gaston1/DEV/ACTIA/workstation/logs/Teachers/Unet', 'silent': 'true'}
2024-07-05 21:45:11,828 INFO    MainThread:43406 [wandb_setup.py:_flush():76] Applying setup settings: {'_disable_service': False}
2024-07-05 21:45:11,828 INFO    MainThread:43406 [wandb_setup.py:_flush():76] Inferring run settings from compute environment: {'program_relpath': 'workstation/scripts/train.py', 'program_abspath': '/media/gaston/gaston1/DEV/ACTIA/workstation/scripts/train.py', 'program': '/media/gaston/gaston1/DEV/ACTIA/workstation/scripts/train.py'}
2024-07-05 21:45:11,829 INFO    MainThread:43406 [wandb_setup.py:_flush():76] Applying login settings: {}
2024-07-05 21:45:11,829 INFO    MainThread:43406 [wandb_setup.py:_flush():76] [34m[1mwandb[0m: Network error (ConnectionError), entering retry loop.
2024-07-05 21:45:11,830 INFO    MainThread:43406 [wandb_init.py:_log_setup():529] Logging user logs to /media/gaston/gaston1/DEV/ACTIA/workstation/logs/Teachers/Unet/wandb/run-20240705_214511-fg5lpugl/logs/debug.log
2024-07-05 21:45:11,831 INFO    MainThread:43406 [wandb_init.py:_log_setup():530] Logging internal logs to /media/gaston/gaston1/DEV/ACTIA/workstation/logs/Teachers/Unet/wandb/run-20240705_214511-fg5lpugl/logs/debug-internal.log
2024-07-05 21:45:11,831 INFO    MainThread:43406 [wandb_init.py:init():569] calling init triggers
2024-07-05 21:45:11,831 INFO    MainThread:43406 [wandb_init.py:init():576] wandb.init called with sweep_config: {}
config: {}
2024-07-05 21:45:11,831 INFO    MainThread:43406 [wandb_init.py:init():619] starting backend
2024-07-05 21:45:11,832 INFO    MainThread:43406 [wandb_init.py:init():623] setting up manager
2024-07-05 21:45:11,843 INFO    MainThread:43406 [backend.py:_multiprocessing_setup():105] multiprocessing start_methods=fork,spawn,forkserver, using: spawn
2024-07-05 21:45:11,849 INFO    MainThread:43406 [wandb_init.py:init():631] backend started and connected
2024-07-05 21:45:11,872 INFO    MainThread:43406 [wandb_init.py:init():720] updated telemetry
2024-07-05 21:45:11,914 INFO    MainThread:43406 [wandb_init.py:init():753] communicating run to backend with 90.0 second timeout
2024-07-05 21:46:41,949 ERROR   MainThread:43406 [wandb_init.py:init():779] encountered error: Run initialization has timed out after 90.0 sec. 
Please refer to the documentation for additional information: https://docs.wandb.ai/guides/track/tracking-faq#initstarterror-error-communicating-with-wandb-process-
2024-07-05 21:46:41,952 ERROR   MainThread:43406 [wandb_init.py:init():1191] error in wandb.init()
Traceback (most recent call last):
  File "/home/gaston/Documents/icreatemodels/lib/python3.10/site-packages/wandb/sdk/wandb_init.py", line 1181, in init
    return wi.init()
  File "/home/gaston/Documents/icreatemodels/lib/python3.10/site-packages/wandb/sdk/wandb_init.py", line 785, in init
    raise error
wandb.errors.CommError: Run initialization has timed out after 90.0 sec. 
Please refer to the documentation for additional information: https://docs.wandb.ai/guides/track/tracking-faq#initstarterror-error-communicating-with-wandb-process-
2024-07-05 21:46:44,301 WARN    MsgRouterThr:43406 [router.py:message_loop():77] message_loop has been closed
