2024-07-05 21:45:11,850 INFO    StreamThr :43497 [internal.py:wandb_internal():85] W&B internal server running at pid: 43497, started at: 2024-07-05 21:45:11.846441
2024-07-05 21:45:11,853 DEBUG   HandlerThread:43497 [handler.py:handle_request():158] handle_request: status
2024-07-05 21:45:11,875 INFO    WriterThread:43497 [datastore.py:open_for_write():87] open: /media/gaston/gaston1/DEV/ACTIA/workstation/logs/Teachers/Unet/wandb/run-20240705_214511-fg5lpugl/run-fg5lpugl.wandb
2024-07-05 21:45:11,876 DEBUG   SenderThread:43497 [sender.py:send():379] send: header
2024-07-05 21:45:11,916 DEBUG   SenderThread:43497 [sender.py:send():379] send: run
2024-07-05 21:45:15,592 INFO    SenderThread:43497 [retry.py:__call__():172] Retry attempt failed:
Traceback (most recent call last):
  File "/home/gaston/Documents/icreatemodels/lib/python3.10/site-packages/urllib3/connection.py", line 174, in _new_conn
    conn = connection.create_connection(
  File "/home/gaston/Documents/icreatemodels/lib/python3.10/site-packages/urllib3/util/connection.py", line 72, in create_connection
    for res in socket.getaddrinfo(host, port, family, socket.SOCK_STREAM):
  File "/usr/lib/python3.10/socket.py", line 955, in getaddrinfo
    for res in _socket.getaddrinfo(host, port, family, type, proto, flags):
socket.gaierror: [Errno -2] Name or service not known

During handling of the above exception, another exception occurred:

Traceback (most recent call last):
  File "/home/gaston/Documents/icreatemodels/lib/python3.10/site-packages/urllib3/connectionpool.py", line 703, in urlopen
    httplib_response = self._make_request(
  File "/home/gaston/Documents/icreatemodels/lib/python3.10/site-packages/urllib3/connectionpool.py", line 386, in _make_request
    self._validate_conn(conn)
  File "/home/gaston/Documents/icreatemodels/lib/python3.10/site-packages/urllib3/connectionpool.py", line 1042, in _validate_conn
    conn.connect()
  File "/home/gaston/Documents/icreatemodels/lib/python3.10/site-packages/urllib3/connection.py", line 363, in connect
    self.sock = conn = self._new_conn()
  File "/home/gaston/Documents/icreatemodels/lib/python3.10/site-packages/urllib3/connection.py", line 186, in _new_conn
    raise NewConnectionError(
urllib3.exceptions.NewConnectionError: <urllib3.connection.HTTPSConnection object at 0x7f34169b3c70>: Failed to establish a new connection: [Errno -2] Name or service not known

During handling of the above exception, another exception occurred:

Traceback (most recent call last):
  File "/home/gaston/Documents/icreatemodels/lib/python3.10/site-packages/requests/adapters.py", line 486, in send
    resp = conn.urlopen(
  File "/home/gaston/Documents/icreatemodels/lib/python3.10/site-packages/urllib3/connectionpool.py", line 787, in urlopen
    retries = retries.increment(
  File "/home/gaston/Documents/icreatemodels/lib/python3.10/site-packages/urllib3/util/retry.py", line 592, in increment
    raise MaxRetryError(_pool, url, error or ResponseError(cause))
urllib3.exceptions.MaxRetryError: HTTPSConnectionPool(host='api.wandb.ai', port=443): Max retries exceeded with url: /graphql (Caused by NewConnectionError('<urllib3.connection.HTTPSConnection object at 0x7f34169b3c70>: Failed to establish a new connection: [Errno -2] Name or service not known'))

During handling of the above exception, another exception occurred:

Traceback (most recent call last):
  File "/home/gaston/Documents/icreatemodels/lib/python3.10/site-packages/wandb/sdk/lib/retry.py", line 131, in __call__
    result = self._call_fn(*args, **kwargs)
  File "/home/gaston/Documents/icreatemodels/lib/python3.10/site-packages/wandb/sdk/internal/internal_api.py", line 345, in execute
    return self.client.execute(*args, **kwargs)  # type: ignore
  File "/home/gaston/Documents/icreatemodels/lib/python3.10/site-packages/wandb/vendor/gql-0.2.0/wandb_gql/client.py", line 52, in execute
    result = self._get_result(document, *args, **kwargs)
  File "/home/gaston/Documents/icreatemodels/lib/python3.10/site-packages/wandb/vendor/gql-0.2.0/wandb_gql/client.py", line 60, in _get_result
    return self.transport.execute(document, *args, **kwargs)
  File "/home/gaston/Documents/icreatemodels/lib/python3.10/site-packages/wandb/sdk/lib/gql_request.py", line 58, in execute
    request = self.session.post(self.url, **post_args)
  File "/home/gaston/Documents/icreatemodels/lib/python3.10/site-packages/requests/sessions.py", line 637, in post
    return self.request("POST", url, data=data, json=json, **kwargs)
  File "/home/gaston/Documents/icreatemodels/lib/python3.10/site-packages/requests/sessions.py", line 589, in request
    resp = self.send(prep, **send_kwargs)
  File "/home/gaston/Documents/icreatemodels/lib/python3.10/site-packages/requests/sessions.py", line 703, in send
    r = adapter.send(request, **kwargs)
  File "/home/gaston/Documents/icreatemodels/lib/python3.10/site-packages/requests/adapters.py", line 519, in send
    raise ConnectionError(e, request=request)
requests.exceptions.ConnectionError: HTTPSConnectionPool(host='api.wandb.ai', port=443): Max retries exceeded with url: /graphql (Caused by NewConnectionError('<urllib3.connection.HTTPSConnection object at 0x7f34169b3c70>: Failed to establish a new connection: [Errno -2] Name or service not known'))
2024-07-05 21:45:16,918 DEBUG   HandlerThread:43497 [handler.py:handle_request():158] handle_request: keepalive
2024-07-05 21:45:21,920 DEBUG   HandlerThread:43497 [handler.py:handle_request():158] handle_request: keepalive
2024-07-05 21:45:26,921 DEBUG   HandlerThread:43497 [handler.py:handle_request():158] handle_request: keepalive
2024-07-05 21:45:31,923 DEBUG   HandlerThread:43497 [handler.py:handle_request():158] handle_request: keepalive
2024-07-05 21:45:36,925 DEBUG   HandlerThread:43497 [handler.py:handle_request():158] handle_request: keepalive
2024-07-05 21:45:41,928 DEBUG   HandlerThread:43497 [handler.py:handle_request():158] handle_request: keepalive
2024-07-05 21:45:46,929 DEBUG   HandlerThread:43497 [handler.py:handle_request():158] handle_request: keepalive
2024-07-05 21:45:51,932 DEBUG   HandlerThread:43497 [handler.py:handle_request():158] handle_request: keepalive
2024-07-05 21:45:56,933 DEBUG   HandlerThread:43497 [handler.py:handle_request():158] handle_request: keepalive
2024-07-05 21:46:01,935 DEBUG   HandlerThread:43497 [handler.py:handle_request():158] handle_request: keepalive
2024-07-05 21:46:06,937 DEBUG   HandlerThread:43497 [handler.py:handle_request():158] handle_request: keepalive
2024-07-05 21:46:11,938 DEBUG   HandlerThread:43497 [handler.py:handle_request():158] handle_request: keepalive
2024-07-05 21:46:16,940 DEBUG   HandlerThread:43497 [handler.py:handle_request():158] handle_request: keepalive
2024-07-05 21:46:21,941 DEBUG   HandlerThread:43497 [handler.py:handle_request():158] handle_request: keepalive
2024-07-05 21:46:26,944 DEBUG   HandlerThread:43497 [handler.py:handle_request():158] handle_request: keepalive
2024-07-05 21:46:31,946 DEBUG   HandlerThread:43497 [handler.py:handle_request():158] handle_request: keepalive
2024-07-05 21:46:36,947 DEBUG   HandlerThread:43497 [handler.py:handle_request():158] handle_request: keepalive
2024-07-05 21:46:41,949 DEBUG   HandlerThread:43497 [handler.py:handle_request():158] handle_request: cancel
2024-07-05 21:46:41,952 DEBUG   HandlerThread:43497 [handler.py:handle_request():158] handle_request: cancel
2024-07-05 21:46:41,953 DEBUG   SenderThread:43497 [sender.py:send():388] Record cancelled: run
2024-07-05 21:46:41,954 DEBUG   HandlerThread:43497 [handler.py:handle_request():158] handle_request: status_report
2024-07-05 21:46:43,299 DEBUG   HandlerThread:43497 [handler.py:handle_request():158] handle_request: shutdown
2024-07-05 21:46:43,300 INFO    HandlerThread:43497 [handler.py:finish():882] shutting down handler
2024-07-05 21:46:43,954 INFO    SenderThread:43497 [sender.py:finish():1608] shutting down sender
2024-07-05 21:46:43,955 INFO    WriterThread:43497 [datastore.py:close():296] close: /media/gaston/gaston1/DEV/ACTIA/workstation/logs/Teachers/Unet/wandb/run-20240705_214511-fg5lpugl/run-fg5lpugl.wandb
